Configuration space code:
from ConfigSpace import ConfigurationSpace, Categorical, Float, Integer, EqualsCondition, ForbiddenAndConjunction, ForbiddenEqualsClause

def get_configspace():
    cs = ConfigurationSpace(seed=1234)
    
    learning_rate = Categorical("learning_rate", ["adaptive", "constant"])
    alpha = Float("alpha", [1e-6, 1e-1], log=True)
    max_iter = Integer("max_iter", [100, 1000])
    eta0 = Float("eta0", [1e-4, 1.0], log=True)
    early_stopping = Categorical("early_stopping", [True, False], default=True)
    
    cs.add_hyperparameters([learning_rate, alpha, max_iter, eta0, early_stopping])
    
    cond_eta0 = EqualsCondition(eta0, learning_rate, "constant")
    cs.add_condition(EqualsCondition(eta0, learning_rate, "constant"))
    
    forbidden_clause = ForbiddenAndConjunction(
        ForbiddenEqualsClause(learning_rate, "constant"),
        ForbiddenEqualsClause(early_stopping, False)
    )
    cs.add_forbidden_clause(forbidden_clause)
    
    return cs

Generated configuration space:
Configuration space object:
  Hyperparameters:
    alpha, Type: UniformFloat, Range: [1e-06, 0.1], Default: 0.000316227766, on log-scale
    early_stopping, Type: Categorical, Choices: {True, False}, Default: True
    eta0, Type: UniformFloat, Range: [0.0001, 1.0], Default: 0.01, on log-scale
    learning_rate, Type: Categorical, Choices: {adaptive, constant}, Default: adaptive
    max_iter, Type: UniformInteger, Range: [100, 1000], Default: 550
  Conditions:
    eta0 | learning_rate == 'constant'
  Forbidden Clauses:
    (Forbidden: learning_rate == 'constant' && Forbidden: early_stopping == False)

Configuration space code:
from ConfigSpace import ConfigurationSpace, Categorical, Float, Integer, EqualsCondition, ForbiddenEqualsClause, ForbiddenAndConjunction

def get_configspace():
    cs = ConfigurationSpace(seed=1234)
    learning_rate = Categorical("learning_rate", ["adaptive", "constant"])
    alpha = Float("alpha", bounds=(1e-6, 1e-1), log=True)
    max_iter = Integer("max_iter", bounds=(100, 1000))
    eta0 = Float("eta0", bounds=(1e-4, 1.0), log=True)
    early_stopping = Categorical("early_stopping", [True, False], default=True)

    cs.add([learning_rate, alpha, max_iter, eta0, early_stopping])

    cond = EqualsCondition(eta0, learning_rate, "constant")
    cs.add_condition(cond)

    forbidden_clause = ForbiddenAndConjunction(
        ForbiddenEqualsClause(learning_rate, "adaptive"),
        ForbiddenEqualsClause(eta0, 0.1)  # Example value, adjust according to your needs
    )
    cs.add_forbidden_clause(forbidden_clause)

    return cs

Generated configuration space:
Configuration space object:
  Hyperparameters:
    alpha, Type: UniformFloat, Range: [1e-06, 0.1], Default: 0.000316227766, on log-scale
    early_stopping, Type: Categorical, Choices: {True, False}, Default: True
    eta0, Type: UniformFloat, Range: [0.0001, 1.0], Default: 0.01, on log-scale
    learning_rate, Type: Categorical, Choices: {adaptive, constant}, Default: adaptive
    max_iter, Type: UniformInteger, Range: [100, 1000], Default: 550
  Conditions:
    eta0 | learning_rate == 'constant'
  Forbidden Clauses:
    (Forbidden: learning_rate == 'adaptive' && Forbidden: eta0 == 0.1)

Scenario code:
from smac import Scenario

def generate_scenario(cs):
    scenario = Scenario({
        "run_obj": "quality",
        "output_dir": "./automl_results",
        "shared_model": False,
        "deterministic": False,
        "limit_resources": True,
        "cs": cs
    })
    return scenario

Generated scenario: Scenario(configspace={'run_obj': 'quality', 'output_dir': './automl_results', 'shared_model': False, 'deterministic': False, 'limit_resources': True, 'cs': Configuration space object:
  Hyperparameters:
    alpha, Type: UniformFloat, Range: [1e-06, 0.1], Default: 0.000316227766, on log-scale
    early_stopping, Type: Categorical, Choices: {True, False}, Default: True
    eta0, Type: UniformFloat, Range: [0.0001, 1.0], Default: 0.01, on log-scale
    learning_rate, Type: Categorical, Choices: {adaptive, constant}, Default: adaptive
    max_iter, Type: UniformInteger, Range: [100, 1000], Default: 550
  Conditions:
    eta0 | learning_rate == 'constant'
  Forbidden Clauses:
    (Forbidden: learning_rate == 'adaptive' && Forbidden: eta0 == 0.1)
}, name=None, output_directory=PosixPath('smac3_output'), deterministic=False, objectives='cost', crash_cost=inf, termination_cost_threshold=inf, walltime_limit=inf, cputime_limit=inf, trial_walltime_limit=None, trial_memory_limit=None, n_trials=100, use_default_config=False, instances=None, instance_features=None, min_budget=None, max_budget=None, seed=0, n_workers=1)
Generated training function code:
```python
from sklearn.model_selection import StratifiedKFold, cross_val_score
from sklearn.linear_model import SGDClassifier
from typing import Any
from ConfigSpace import Configuration

def train(cfg: Configuration, seed: int, dataset: Any) -> float:
    X: Any = dataset['X']
    y: Any = dataset['y']
    learning_rate: str = cfg.get('learning_rate')
    alpha: float = cfg.get('alpha')
    max_iter: int = cfg.get('max_iter')
    eta0: float = cfg.get('eta0')

    C: float = 1.0 / alpha
    params: dict = {
        'loss': 'log_loss',
        'penalty': 'l2',
        'learning_rate': learning_rate,
        'C': C,
        'max_iter': max_iter,
        'warm_start': True,
        'random_state': seed,
    }

    if learning_rate == 'constant':
        params['eta0'] = eta0

    model: SGDClassifier = SGDClassifier(**params)
    cv: StratifiedKFold = StratifiedKFold(n_splits=5, shuffle=True, random_state=seed)
    scores: Any = cross_val_score(model, X, y, cv=cv, scoring='accuracy')
    return 1.0 - scores.mean()
```
Error occurred: __init__() got an unexpected keyword argument 'C'
_inform_errors_to_llm**Prompt for LLM:
The following python code is generated by an LLM which now has run into the following errors:
__init__() got an unexpected keyword argument 'C'

Your task is to fix the issues in the code. The requirements below MUST be respected:

1. Do not change the function name or its purpose.
2. Fix all syntax and runtime errors.
3. Use only valid parameters.
4. Do not change the logic unless necessary for fixing errors.
5. Return ONLY the corrected function code â€” no explanations, comments, or extra output.
6. The function must be syntactically and semantically correct, and executable with `exec`.

Buggy code:
from sklearn.model_selection import StratifiedKFold, cross_val_score
from sklearn.linear_model import SGDClassifier
from typing import Any
from ConfigSpace import Configuration

def train(cfg: Configuration, seed: int, dataset: Any) -> float:
    X: Any = dataset['X']
    y: Any = dataset['y']
    learning_rate: str = cfg.get('learning_rate')
    alpha: float = cfg.get('alpha')
    max_iter: int = cfg.get('max_iter')
    eta0: float = cfg.get('eta0')

    C: float = 1.0 / alpha
    params: dict = {
        'loss': 'log_loss',
        'penalty': 'l2',
        'learning_rate': learning_rate,
        'C': C,
        'max_iter': max_iter,
        'warm_start': True,
        'random_state': seed,
    }

    if learning_rate == 'constant':
        params['eta0'] = eta0

    model: SGDClassifier = SGDClassifier(**params)
    cv: StratifiedKFold = StratifiedKFold(n_splits=5, shuffle=True, random_state=seed)
    scores: Any = cross_val_score(model, X, y, cv=cv, scoring='accuracy')
    return 1.0 - scores.mean()


Error occurred: 
All the 5 fits failed.
It is very likely that your model is misconfigured.
You can try to debug the error by setting error_score='raise'.

Below are more details about the failures:
--------------------------------------------------------------------------------
5 fits failed with the following error:
Traceback (most recent call last):
  File "/Users/amirrezaalasti/.pyenv/versions/3.9.13/lib/python3.9/site-packages/sklearn/model_selection/_validation.py", line 888, in _fit_and_score
    estimator.fit(X_train, y_train, **fit_params)
  File "/Users/amirrezaalasti/.pyenv/versions/3.9.13/lib/python3.9/site-packages/sklearn/base.py", line 1473, in wrapper
    return fit_method(estimator, *args, **kwargs)
  File "/Users/amirrezaalasti/.pyenv/versions/3.9.13/lib/python3.9/site-packages/sklearn/linear_model/_stochastic_gradient.py", line 936, in fit
    self._more_validate_params()
  File "/Users/amirrezaalasti/.pyenv/versions/3.9.13/lib/python3.9/site-packages/sklearn/linear_model/_stochastic_gradient.py", line 153, in _more_validate_params
    raise ValueError("eta0 must be > 0")
ValueError: eta0 must be > 0

_inform_errors_to_llm**Prompt for LLM:
The following python code is generated by an LLM which now has run into the following errors:
__init__() got an unexpected keyword argument 'C'

All the 5 fits failed.
It is very likely that your model is misconfigured.
You can try to debug the error by setting error_score='raise'.

Below are more details about the failures:
--------------------------------------------------------------------------------
5 fits failed with the following error:
Traceback (most recent call last):
  File "/Users/amirrezaalasti/.pyenv/versions/3.9.13/lib/python3.9/site-packages/sklearn/model_selection/_validation.py", line 888, in _fit_and_score
    estimator.fit(X_train, y_train, **fit_params)
  File "/Users/amirrezaalasti/.pyenv/versions/3.9.13/lib/python3.9/site-packages/sklearn/base.py", line 1473, in wrapper
    return fit_method(estimator, *args, **kwargs)
  File "/Users/amirrezaalasti/.pyenv/versions/3.9.13/lib/python3.9/site-packages/sklearn/linear_model/_stochastic_gradient.py", line 936, in fit
    self._more_validate_params()
  File "/Users/amirrezaalasti/.pyenv/versions/3.9.13/lib/python3.9/site-packages/sklearn/linear_model/_stochastic_gradient.py", line 153, in _more_validate_params
    raise ValueError("eta0 must be > 0")
ValueError: eta0 must be > 0


Your task is to fix the issues in the code. The requirements below MUST be respected:

1. Do not change the function name or its purpose.
2. Fix all syntax and runtime errors.
3. Use only valid parameters.
4. Do not change the logic unless necessary for fixing errors.
5. Return ONLY the corrected function code â€” no explanations, comments, or extra output.
6. The function must be syntactically and semantically correct, and executable with `exec`.

Buggy code:
from sklearn.model_selection import StratifiedKFold, cross_val_score
from sklearn.linear_model import SGDClassifier
from typing import Any
from ConfigSpace import Configuration

def train(cfg: Configuration, seed: int, dataset: Any) -> float:
    X: Any = dataset['X']
    y: Any = dataset['y']
    learning_rate: str = cfg.get('learning_rate')
    alpha: float = cfg.get('alpha')
    max_iter: int = cfg.get('max_iter')
    eta0: float = cfg.get('eta0')

    params: dict = {
        'loss': 'log_loss',
        'penalty': 'l2',
        'learning_rate': learning_rate,
        'alpha': 1.0 / (alpha if alpha != 0 else 1e-6), # Avoid division by zero
        'max_iter': max_iter,
        'warm_start': True,
        'random_state': seed,
    }

    if learning_rate == 'constant':
        params['eta0'] = eta0

    model: SGDClassifier = SGDClassifier(**params)
    cv: StratifiedKFold = StratifiedKFold(n_splits=5, shuffle=True, random_state=seed)
    scores: Any = cross_val_score(model, X, y, cv=cv, scoring='accuracy')
    return 1.0 - scores.mean()


Error occurred: 
All the 5 fits failed.
It is very likely that your model is misconfigured.
You can try to debug the error by setting error_score='raise'.

Below are more details about the failures:
--------------------------------------------------------------------------------
5 fits failed with the following error:
Traceback (most recent call last):
  File "/Users/amirrezaalasti/.pyenv/versions/3.9.13/lib/python3.9/site-packages/sklearn/model_selection/_validation.py", line 888, in _fit_and_score
    estimator.fit(X_train, y_train, **fit_params)
  File "/Users/amirrezaalasti/.pyenv/versions/3.9.13/lib/python3.9/site-packages/sklearn/base.py", line 1473, in wrapper
    return fit_method(estimator, *args, **kwargs)
  File "/Users/amirrezaalasti/.pyenv/versions/3.9.13/lib/python3.9/site-packages/sklearn/linear_model/_stochastic_gradient.py", line 936, in fit
    self._more_validate_params()
  File "/Users/amirrezaalasti/.pyenv/versions/3.9.13/lib/python3.9/site-packages/sklearn/linear_model/_stochastic_gradient.py", line 153, in _more_validate_params
    raise ValueError("eta0 must be > 0")
ValueError: eta0 must be > 0

_inform_errors_to_llm**Prompt for LLM:
The following python code is generated by an LLM which now has run into the following errors:
__init__() got an unexpected keyword argument 'C'

All the 5 fits failed.
It is very likely that your model is misconfigured.
You can try to debug the error by setting error_score='raise'.

Below are more details about the failures:
--------------------------------------------------------------------------------
5 fits failed with the following error:
Traceback (most recent call last):
  File "/Users/amirrezaalasti/.pyenv/versions/3.9.13/lib/python3.9/site-packages/sklearn/model_selection/_validation.py", line 888, in _fit_and_score
    estimator.fit(X_train, y_train, **fit_params)
  File "/Users/amirrezaalasti/.pyenv/versions/3.9.13/lib/python3.9/site-packages/sklearn/base.py", line 1473, in wrapper
    return fit_method(estimator, *args, **kwargs)
  File "/Users/amirrezaalasti/.pyenv/versions/3.9.13/lib/python3.9/site-packages/sklearn/linear_model/_stochastic_gradient.py", line 936, in fit
    self._more_validate_params()
  File "/Users/amirrezaalasti/.pyenv/versions/3.9.13/lib/python3.9/site-packages/sklearn/linear_model/_stochastic_gradient.py", line 153, in _more_validate_params
    raise ValueError("eta0 must be > 0")
ValueError: eta0 must be > 0


All the 5 fits failed.
It is very likely that your model is misconfigured.
You can try to debug the error by setting error_score='raise'.

Below are more details about the failures:
--------------------------------------------------------------------------------
5 fits failed with the following error:
Traceback (most recent call last):
  File "/Users/amirrezaalasti/.pyenv/versions/3.9.13/lib/python3.9/site-packages/sklearn/model_selection/_validation.py", line 888, in _fit_and_score
    estimator.fit(X_train, y_train, **fit_params)
  File "/Users/amirrezaalasti/.pyenv/versions/3.9.13/lib/python3.9/site-packages/sklearn/base.py", line 1473, in wrapper
    return fit_method(estimator, *args, **kwargs)
  File "/Users/amirrezaalasti/.pyenv/versions/3.9.13/lib/python3.9/site-packages/sklearn/linear_model/_stochastic_gradient.py", line 936, in fit
    self._more_validate_params()
  File "/Users/amirrezaalasti/.pyenv/versions/3.9.13/lib/python3.9/site-packages/sklearn/linear_model/_stochastic_gradient.py", line 153, in _more_validate_params
    raise ValueError("eta0 must be > 0")
ValueError: eta0 must be > 0


Your task is to fix the issues in the code. The requirements below MUST be respected:

1. Do not change the function name or its purpose.
2. Fix all syntax and runtime errors.
3. Use only valid parameters.
4. Do not change the logic unless necessary for fixing errors.
5. Return ONLY the corrected function code â€” no explanations, comments, or extra output.
6. The function must be syntactically and semantically correct, and executable with `exec`.

Buggy code:
from sklearn.model_selection import StratifiedKFold, cross_val_score
from sklearn.linear_model import SGDClassifier
from typing import Any
from ConfigSpace import Configuration

def train(cfg: Configuration, seed: int, dataset: Any) -> float:
    X: Any = dataset['X']
    y: Any = dataset['y']
    learning_rate: str = cfg.get('learning_rate')
    alpha: float = cfg.get('alpha')
    max_iter: int = cfg.get('max_iter')
    eta0: float = cfg.get('eta0')

    params: dict = {
        'loss': 'log_loss',
        'penalty': 'l2',
        'learning_rate': learning_rate,
        'alpha': 1.0 / (alpha if alpha != 0 else 1e-6),  # Avoid division by zero
        'max_iter': max_iter,
        'warm_start': True,
        'random_state': seed,
    }

    if learning_rate == 'constant':
        params['eta0'] = max(eta0, 1e-6)  # Ensure eta0 is greater than 0

    model: SGDClassifier = SGDClassifier(**params)
    cv: StratifiedKFold = StratifiedKFold(n_splits=5, shuffle=True, random_state=seed)
    scores: Any = cross_val_score(model, X, y, cv=cv, scoring='accuracy')
    return 1.0 - scores.mean()


Error occurred: '>' not supported between instances of 'float' and 'NoneType'
_inform_errors_to_llm**Prompt for LLM:
The following python code is generated by an LLM which now has run into the following errors:

All the 5 fits failed.
It is very likely that your model is misconfigured.
You can try to debug the error by setting error_score='raise'.

Below are more details about the failures:
--------------------------------------------------------------------------------
5 fits failed with the following error:
Traceback (most recent call last):
  File "/Users/amirrezaalasti/.pyenv/versions/3.9.13/lib/python3.9/site-packages/sklearn/model_selection/_validation.py", line 888, in _fit_and_score
    estimator.fit(X_train, y_train, **fit_params)
  File "/Users/amirrezaalasti/.pyenv/versions/3.9.13/lib/python3.9/site-packages/sklearn/base.py", line 1473, in wrapper
    return fit_method(estimator, *args, **kwargs)
  File "/Users/amirrezaalasti/.pyenv/versions/3.9.13/lib/python3.9/site-packages/sklearn/linear_model/_stochastic_gradient.py", line 936, in fit
    self._more_validate_params()
  File "/Users/amirrezaalasti/.pyenv/versions/3.9.13/lib/python3.9/site-packages/sklearn/linear_model/_stochastic_gradient.py", line 153, in _more_validate_params
    raise ValueError("eta0 must be > 0")
ValueError: eta0 must be > 0


All the 5 fits failed.
It is very likely that your model is misconfigured.
You can try to debug the error by setting error_score='raise'.

Below are more details about the failures:
--------------------------------------------------------------------------------
5 fits failed with the following error:
Traceback (most recent call last):
  File "/Users/amirrezaalasti/.pyenv/versions/3.9.13/lib/python3.9/site-packages/sklearn/model_selection/_validation.py", line 888, in _fit_and_score
    estimator.fit(X_train, y_train, **fit_params)
  File "/Users/amirrezaalasti/.pyenv/versions/3.9.13/lib/python3.9/site-packages/sklearn/base.py", line 1473, in wrapper
    return fit_method(estimator, *args, **kwargs)
  File "/Users/amirrezaalasti/.pyenv/versions/3.9.13/lib/python3.9/site-packages/sklearn/linear_model/_stochastic_gradient.py", line 936, in fit
    self._more_validate_params()
  File "/Users/amirrezaalasti/.pyenv/versions/3.9.13/lib/python3.9/site-packages/sklearn/linear_model/_stochastic_gradient.py", line 153, in _more_validate_params
    raise ValueError("eta0 must be > 0")
ValueError: eta0 must be > 0

'>' not supported between instances of 'float' and 'NoneType'

Your task is to fix the issues in the code. The requirements below MUST be respected:

1. Do not change the function name or its purpose.
2. Fix all syntax and runtime errors.
3. Use only valid parameters.
4. Do not change the logic unless necessary for fixing errors.
5. Return ONLY the corrected function code â€” no explanations, comments, or extra output.
6. The function must be syntactically and semantically correct, and executable with `exec`.

Buggy code:
from sklearn.model_selection import StratifiedKFold, cross_val_score
from sklearn.linear_model import SGDClassifier
from typing import Any
from ConfigSpace import Configuration

def train(cfg: Configuration, seed: int, dataset: Any) -> float:
    X: Any = dataset['X']
    y: Any = dataset['y']
    learning_rate: str = cfg.get('learning_rate')
    alpha: float = cfg.get('alpha')
    max_iter: int = cfg.get('max_iter')
    eta0: float = cfg.get('eta0')

    params: dict = {
        'loss': 'log_loss',
        'penalty': 'l2',
        'learning_rate': learning_rate,
        'alpha': 1.0 / (alpha if alpha != 0 else 1e-6),  # Avoid division by zero
        'max_iter': max_iter,
        'random_state': seed,
    }

    if learning_rate == 'constant' or learning_rate == 'invscaling' or learning_rate == 'adaptive':
        params['eta0'] = max(eta0, 1e-6)  # Ensure eta0 is greater than 0

    model: SGDClassifier = SGDClassifier(**params)
    cv: StratifiedKFold = StratifiedKFold(n_splits=5, shuffle=True, random_state=seed)
    scores: Any = cross_val_score(model, X, y, cv=cv, scoring='accuracy', error_score='raise')
    return 1.0 - scores.mean()


Training function executed successfully.
Training function executed successfully.
Loss: 0.6666666666666667
Configuration space code:
from ConfigSpace import ConfigurationSpace, Categorical, Float, Integer, EqualsCondition, ForbiddenAndConjunction, ForbiddenEqualsClause

def get_configspace():
    # Hyperparameters
    learning_rate = Categorical(
        name="learning_rate",
        choices=["adaptive", "constant"]
    )
    
    alpha = Float(
        name="alpha",
        lower=1e-6,
        upper=1e-1,
        log=True
    )
    
    max_iter = Integer(
        name="max_iter",
        lower=100,
        upper=1000
    )
    
    eta0 = Float(
        name="eta0",
        lower=1e-4,
        upper=1.0,
        log=True
    )
    
    early_stopping = Categorical(
        name="early_stopping",
        choices=[True, False],
        default=True
    )
    
    # Conditions
    condition_eta0 = EqualsCondition(
        child=eta0,
        parent=learning_rate,
        values=["constant"]
    )
    
    # Forbidden Clauses
    forbidden_clause = ForbiddenAndConjunction(
        forbidden_clauses=[
            ForbiddenEqualsClause(learning_rate, "adaptive"),
            ForbiddenEqualsClause(early_stopping, False)
        ]
    )
    
    # Configuration Space
    cs = ConfigurationSpace(seed=1234)
    cs.add_hyperparameters([learning_rate, alpha, max_iter, eta0, early_stopping])
    cs.add_condition(condition_eta0)
    cs.add_forbidden_clause(forbidden_clause)
    
    return cs

Error occurred: Categorical() got an unexpected keyword argument 'choices'
_inform_errors_to_llm**Prompt for LLM:
The following python code is generated by an LLM which now has run into the following errors:
Categorical() got an unexpected keyword argument 'choices'

Your task is to fix the issues in the code. The requirements below MUST be respected:

1. Do not change the function name or its purpose.
2. Fix all syntax and runtime errors.
3. Use only valid parameters.
4. Do not change the logic unless necessary for fixing errors.
5. Return ONLY the corrected function code â€” no explanations, comments, or extra output.
6. The function must be syntactically and semantically correct, and executable with `exec`.

Buggy code:
from ConfigSpace import ConfigurationSpace, Categorical, Float, Integer, EqualsCondition, ForbiddenAndConjunction, ForbiddenEqualsClause

def get_configspace():
    # Hyperparameters
    learning_rate = Categorical(
        name="learning_rate",
        choices=["adaptive", "constant"]
    )
    
    alpha = Float(
        name="alpha",
        lower=1e-6,
        upper=1e-1,
        log=True
    )
    
    max_iter = Integer(
        name="max_iter",
        lower=100,
        upper=1000
    )
    
    eta0 = Float(
        name="eta0",
        lower=1e-4,
        upper=1.0,
        log=True
    )
    
    early_stopping = Categorical(
        name="early_stopping",
        choices=[True, False],
        default=True
    )
    
    # Conditions
    condition_eta0 = EqualsCondition(
        child=eta0,
        parent=learning_rate,
        values=["constant"]
    )
    
    # Forbidden Clauses
    forbidden_clause = ForbiddenAndConjunction(
        forbidden_clauses=[
            ForbiddenEqualsClause(learning_rate, "adaptive"),
            ForbiddenEqualsClause(early_stopping, False)
        ]
    )
    
    # Configuration Space
    cs = ConfigurationSpace(seed=1234)
    cs.add_hyperparameters([learning_rate, alpha, max_iter, eta0, early_stopping])
    cs.add_condition(condition_eta0)
    cs.add_forbidden_clause(forbidden_clause)
    
    return cs


Configuration space code:

Error occurred: Categorical() got an unexpected keyword argument 'choices'
_inform_errors_to_llm**Prompt for LLM:
The following python code is generated by an LLM which now has run into the following errors:
Categorical() got an unexpected keyword argument 'choices'
Categorical() got an unexpected keyword argument 'choices'

Your task is to fix the issues in the code. The requirements below MUST be respected:

1. Do not change the function name or its purpose.
2. Fix all syntax and runtime errors.
3. Use only valid parameters.
4. Do not change the logic unless necessary for fixing errors.
5. Return ONLY the corrected function code â€” no explanations, comments, or extra output.
6. The function must be syntactically and semantically correct, and executable with `exec`.

Buggy code:


Configuration space code:
import pandas as pd

def convert_to_categorical(df, column, categories=None):
    if categories is None:
        categories = df[column].unique()
    df[column] = pd.Categorical(df[column], categories=categories, ordered=False)
    df[column] = df[column].cat.codes
    return df

Error occurred: Categorical() got an unexpected keyword argument 'choices'
_inform_errors_to_llm**Prompt for LLM:
The following python code is generated by an LLM which now has run into the following errors:
Categorical() got an unexpected keyword argument 'choices'
Categorical() got an unexpected keyword argument 'choices'
Categorical() got an unexpected keyword argument 'choices'

Your task is to fix the issues in the code. The requirements below MUST be respected:

1. Do not change the function name or its purpose.
2. Fix all syntax and runtime errors.
3. Use only valid parameters.
4. Do not change the logic unless necessary for fixing errors.
5. Return ONLY the corrected function code â€” no explanations, comments, or extra output.
6. The function must be syntactically and semantically correct, and executable with `exec`.

Buggy code:
import pandas as pd

def convert_to_categorical(df, column, categories=None):
    if categories is None:
        categories = df[column].unique()
    df[column] = pd.Categorical(df[column], categories=categories, ordered=False)
    df[column] = df[column].cat.codes
    return df


Configuration space code:
import pandas as pd

def convert_to_categorical(df, column, categories=None):
    if categories is None:
        categories = df[column].unique()
    df[column] = pd.Categorical(df[column], categories, ordered=False)
    df[column] = df[column].cat.codes
    return df

Error occurred: Categorical() got an unexpected keyword argument 'choices'
_inform_errors_to_llm**Prompt for LLM:
The following python code is generated by an LLM which now has run into the following errors:
Categorical() got an unexpected keyword argument 'choices'
Categorical() got an unexpected keyword argument 'choices'
Categorical() got an unexpected keyword argument 'choices'

Your task is to fix the issues in the code. The requirements below MUST be respected:

1. Do not change the function name or its purpose.
2. Fix all syntax and runtime errors.
3. Use only valid parameters.
4. Do not change the logic unless necessary for fixing errors.
5. Return ONLY the corrected function code â€” no explanations, comments, or extra output.
6. The function must be syntactically and semantically correct, and executable with `exec`.

Buggy code:
import pandas as pd

def convert_to_categorical(df, column, categories=None):
    if categories is None:
        categories = df[column].unique()
    df[column] = pd.Categorical(df[column], categories, ordered=False)
    df[column] = df[column].cat.codes
    return df


Configuration space code:
import pandas as pd

def convert_to_categorical(df, column, categories=None):
    if categories is None:
        categories = df[column].unique()
    df[column] = pd.Categorical(df[column], categories=categories, ordered=False)
    df[column] = df[column].cat.codes
    return df

Error occurred: Categorical() got an unexpected keyword argument 'choices'
_inform_errors_to_llm**Prompt for LLM:
The following python code is generated by an LLM which now has run into the following errors:
Categorical() got an unexpected keyword argument 'choices'
Categorical() got an unexpected keyword argument 'choices'
Categorical() got an unexpected keyword argument 'choices'

Your task is to fix the issues in the code. The requirements below MUST be respected:

1. Do not change the function name or its purpose.
2. Fix all syntax and runtime errors.
3. Use only valid parameters.
4. Do not change the logic unless necessary for fixing errors.
5. Return ONLY the corrected function code â€” no explanations, comments, or extra output.
6. The function must be syntactically and semantically correct, and executable with `exec`.

Buggy code:
import pandas as pd

def convert_to_categorical(df, column, categories=None):
    if categories is None:
        categories = df[column].unique()
    df[column] = pd.Categorical(df[column], categories=categories, ordered=False)
    df[column] = df[column].cat.codes
    return df


Configuration space code:
import pandas as pd

def convert_to_categorical(df, column, categories=None):
    if categories is None:
        categories = df[column].unique()
    df[column] = pd.Categorical(df[column], categories, False)
    df[column] = df[column].cat.codes
    return df

Error occurred: Categorical() got an unexpected keyword argument 'choices'
_inform_errors_to_llm**Prompt for LLM:
The following python code is generated by an LLM which now has run into the following errors:
Categorical() got an unexpected keyword argument 'choices'
Categorical() got an unexpected keyword argument 'choices'
Categorical() got an unexpected keyword argument 'choices'

Your task is to fix the issues in the code. The requirements below MUST be respected:

1. Do not change the function name or its purpose.
2. Fix all syntax and runtime errors.
3. Use only valid parameters.
4. Do not change the logic unless necessary for fixing errors.
5. Return ONLY the corrected function code â€” no explanations, comments, or extra output.
6. The function must be syntactically and semantically correct, and executable with `exec`.

Buggy code:
import pandas as pd

def convert_to_categorical(df, column, categories=None):
    if categories is None:
        categories = df[column].unique()
    df[column] = pd.Categorical(df[column], categories, False)
    df[column] = df[column].cat.codes
    return df


Configuration space code:
import pandas as pd

def convert_to_categorical(df, column, categories=None):
    if categories is None:
        categories = df[column].unique()
    df[column] = pd.Categorical(df[column], categories=categories, ordered=False)
    df[column] = df[column].cat.codes
    return df

Error occurred: Categorical() got an unexpected keyword argument 'choices'
_inform_errors_to_llm**Prompt for LLM:
The following python code is generated by an LLM which now has run into the following errors:
Categorical() got an unexpected keyword argument 'choices'
Categorical() got an unexpected keyword argument 'choices'
Categorical() got an unexpected keyword argument 'choices'

Your task is to fix the issues in the code. The requirements below MUST be respected:

1. Do not change the function name or its purpose.
2. Fix all syntax and runtime errors.
3. Use only valid parameters.
4. Do not change the logic unless necessary for fixing errors.
5. Return ONLY the corrected function code â€” no explanations, comments, or extra output.
6. The function must be syntactically and semantically correct, and executable with `exec`.

Buggy code:
import pandas as pd

def convert_to_categorical(df, column, categories=None):
    if categories is None:
        categories = df[column].unique()
    df[column] = pd.Categorical(df[column], categories=categories, ordered=False)
    df[column] = df[column].cat.codes
    return df


Configuration space code:
import pandas as pd

def convert_to_categorical(df, column, categories=None):
    if categories is None:
        categories = df[column].unique()
    df[column] = pd.Categorical(df[column], ordered=False)
    if categories is not None:
        df[column] = df[column].cat.set_categories(categories)
    df[column] = df[column].cat.codes
    return df

Error occurred: Categorical() got an unexpected keyword argument 'choices'
_inform_errors_to_llm**Prompt for LLM:
The following python code is generated by an LLM which now has run into the following errors:
Categorical() got an unexpected keyword argument 'choices'
Categorical() got an unexpected keyword argument 'choices'
Categorical() got an unexpected keyword argument 'choices'

Your task is to fix the issues in the code. The requirements below MUST be respected:

1. Do not change the function name or its purpose.
2. Fix all syntax and runtime errors.
3. Use only valid parameters.
4. Do not change the logic unless necessary for fixing errors.
5. Return ONLY the corrected function code â€” no explanations, comments, or extra output.
6. The function must be syntactically and semantically correct, and executable with `exec`.

Buggy code:
import pandas as pd

def convert_to_categorical(df, column, categories=None):
    if categories is None:
        categories = df[column].unique()
    df[column] = pd.Categorical(df[column], ordered=False)
    if categories is not None:
        df[column] = df[column].cat.set_categories(categories)
    df[column] = df[column].cat.codes
    return df


Running config code:
from ConfigSpace import ConfigurationSpace, Categorical, Float, Integer, EqualsCondition, ForbiddenEqualsClause, ForbiddenAndConjunction

def get_configspace():
    cs = ConfigurationSpace(seed=1234)
    learning_rate = Categorical("learning_rate", ["adaptive", "constant"])
    alpha = Float("alpha", bounds=(1e-6, 1e-1), log=True)
    max_iter = Integer("max_iter", bounds=(100, 1000))
    eta0 = Float("eta0", bounds=(1e-4, 1.0), log=True)
    early_stopping = Categorical("early_stopping", [True, False], default=True)

    cs.add([learning_rate, alpha, max_iter, eta0, early_stopping])

    cond = EqualsCondition(eta0, learning_rate, "constant")
    cs.add_condition(cond)

    forbidden_clause = ForbiddenAndConjunction(
        ForbiddenEqualsClause(learning_rate, "adaptive"),
        ForbiddenEqualsClause(eta0, 0.1)  # Example value, adjust according to your needs
    )
    cs.add_forbidden_clause(forbidden_clause)

    return cs

Configuration space generated: Configuration space object:
  Hyperparameters:
    alpha, Type: UniformFloat, Range: [1e-06, 0.1], Default: 0.000316227766, on log-scale
    early_stopping, Type: Categorical, Choices: {True, False}, Default: True
    eta0, Type: UniformFloat, Range: [0.0001, 1.0], Default: 0.01, on log-scale
    learning_rate, Type: Categorical, Choices: {adaptive, constant}, Default: adaptive
    max_iter, Type: UniformInteger, Range: [100, 1000], Default: 550
  Conditions:
    eta0 | learning_rate == 'constant'
  Forbidden Clauses:
    (Forbidden: learning_rate == 'adaptive' && Forbidden: eta0 == 0.1)

Running scenario code:
from smac import Scenario

def generate_scenario(cs):
    scenario = Scenario({
        "run_obj": "quality",
        "output_dir": "./automl_results",
        "shared_model": False,
        "deterministic": False,
        "limit_resources": True,
        "cs": cs
    })
    return scenario

Scenario generated: Scenario(configspace={'run_obj': 'quality', 'output_dir': './automl_results', 'shared_model': False, 'deterministic': False, 'limit_resources': True, 'cs': Configuration space object:
  Hyperparameters:
    alpha, Type: UniformFloat, Range: [1e-06, 0.1], Default: 0.000316227766, on log-scale
    early_stopping, Type: Categorical, Choices: {True, False}, Default: True
    eta0, Type: UniformFloat, Range: [0.0001, 1.0], Default: 0.01, on log-scale
    learning_rate, Type: Categorical, Choices: {adaptive, constant}, Default: adaptive
    max_iter, Type: UniformInteger, Range: [100, 1000], Default: 550
  Conditions:
    eta0 | learning_rate == 'constant'
  Forbidden Clauses:
    (Forbidden: learning_rate == 'adaptive' && Forbidden: eta0 == 0.1)
}, name=None, output_directory=PosixPath('smac3_output'), deterministic=False, objectives='cost', crash_cost=inf, termination_cost_threshold=inf, walltime_limit=inf, cputime_limit=inf, trial_walltime_limit=None, trial_memory_limit=None, n_trials=100, use_default_config=False, instances=None, instance_features=None, min_budget=None, max_budget=None, seed=0, n_workers=1)
Generated training function code:
```python
from sklearn.model_selection import StratifiedKFold, cross_val_score
from sklearn.linear_model import SGDClassifier
from typing import Any
from ConfigSpace import Configuration

def train(cfg: Configuration, seed: int, dataset: Any) -> float:
    X: Any = dataset['X']
    y: Any = dataset['y']
    learning_rate: str = cfg.get('learning_rate')
    alpha: float = cfg.get('alpha')
    max_iter: int = cfg.get('max_iter')
    eta0: float = cfg.get('eta0')

    C: float = 1.0 / alpha
    params: dict = {
        'loss': 'log_loss',
        'penalty': 'l2',
        'learning_rate': learning_rate,
        'C': C,
        'max_iter': max_iter,
        'warm_start': True,
        'random_state': seed,
    }

    if learning_rate == 'constant':
        params['eta0'] = eta0

    model: SGDClassifier = SGDClassifier(**params)
    cv: StratifiedKFold = StratifiedKFold(n_splits=5, shuffle=True, random_state=seed)
    scores: Any = cross_val_score(model, X, y, cv=cv, scoring='accuracy')
    return 1.0 - scores.mean()
```
Running train_function code:
from sklearn.model_selection import StratifiedKFold, cross_val_score
from sklearn.linear_model import SGDClassifier
from typing import Any
from ConfigSpace import Configuration

def train(cfg: Configuration, seed: int, dataset: Any) -> float:
    X: Any = dataset['X']
    y: Any = dataset['y']
    learning_rate: str = cfg.get('learning_rate')
    alpha: float = cfg.get('alpha')
    max_iter: int = cfg.get('max_iter')
    eta0: float = cfg.get('eta0')

    C: float = 1.0 / alpha
    params: dict = {
        'loss': 'log_loss',
        'penalty': 'l2',
        'learning_rate': learning_rate,
        'C': C,
        'max_iter': max_iter,
        'warm_start': True,
        'random_state': seed,
    }

    if learning_rate == 'constant':
        params['eta0'] = eta0

    model: SGDClassifier = SGDClassifier(**params)
    cv: StratifiedKFold = StratifiedKFold(n_splits=5, shuffle=True, random_state=seed)
    scores: Any = cross_val_score(model, X, y, cv=cv, scoring='accuracy')
    return 1.0 - scores.mean()

Error in train_function (#1): __init__() got an unexpected keyword argument 'C'
Running train_function code:
from sklearn.model_selection import StratifiedKFold, cross_val_score
from sklearn.linear_model import SGDClassifier
from typing import Any
from ConfigSpace import Configuration

def train(cfg: Configuration, seed: int, dataset: Any) -> float:
    X: Any = dataset['X']
    y: Any = dataset['y']
    learning_rate: str = cfg.get('learning_rate')
    alpha: float = cfg.get('alpha')
    max_iter: int = cfg.get('max_iter')
    eta0: float = cfg.get('eta0')

    params: dict = {
        'loss': 'log_loss',
        'penalty': 'l2',
        'learning_rate': learning_rate,
        'alpha': alpha,
        'max_iter': max_iter,
        'warm_start': True,
        'random_state': seed,
    }

    if learning_rate == 'constant':
        params['eta0'] = eta0

    model: SGDClassifier = SGDClassifier(**params)
    cv: StratifiedKFold = StratifiedKFold(n_splits=5, shuffle=True, random_state=seed)
    scores: Any = cross_val_score(model, X, y, cv=cv, scoring='accuracy')
    return 1.0 - scores.mean()

Error in train_function (#2): 
All the 5 fits failed.
It is very likely that your model is misconfigured.
You can try to debug the error by setting error_score='raise'.

Below are more details about the failures:
--------------------------------------------------------------------------------
5 fits failed with the following error:
Traceback (most recent call last):
  File "/Users/amirrezaalasti/.pyenv/versions/3.9.13/lib/python3.9/site-packages/sklearn/model_selection/_validation.py", line 888, in _fit_and_score
    estimator.fit(X_train, y_train, **fit_params)
  File "/Users/amirrezaalasti/.pyenv/versions/3.9.13/lib/python3.9/site-packages/sklearn/base.py", line 1473, in wrapper
    return fit_method(estimator, *args, **kwargs)
  File "/Users/amirrezaalasti/.pyenv/versions/3.9.13/lib/python3.9/site-packages/sklearn/linear_model/_stochastic_gradient.py", line 936, in fit
    self._more_validate_params()
  File "/Users/amirrezaalasti/.pyenv/versions/3.9.13/lib/python3.9/site-packages/sklearn/linear_model/_stochastic_gradient.py", line 153, in _more_validate_params
    raise ValueError("eta0 must be > 0")
ValueError: eta0 must be > 0

Running train_function code:
from sklearn.model_selection import StratifiedKFold, cross_val_score
from sklearn.linear_model import SGDClassifier
from typing import Any
from ConfigSpace import Configuration

def train(cfg: Configuration, seed: int, dataset: Any) -> float:
    X: Any = dataset['X']
    y: Any = dataset['y']
    learning_rate: str = cfg.get('learning_rate')
    alpha: float = cfg.get('alpha')
    max_iter: int = cfg.get('max_iter')
    eta0: float = cfg.get('eta0')

    params: dict = {
        'loss': 'log_loss',
        'penalty': 'l2',
        'learning_rate': learning_rate,
        'alpha': alpha,
        'max_iter': max_iter,
        'warm_start': True,
        'random_state': seed,
    }

    if learning_rate == 'constant' or learning_rate == 'invscaling' or learning_rate == 'adaptive':
        params['eta0'] = eta0

    model: SGDClassifier = SGDClassifier(**params)
    cv: StratifiedKFold = StratifiedKFold(n_splits=5, shuffle=True, random_state=seed)
    scores: Any = cross_val_score(model, X, y, cv=cv, scoring='accuracy', error_score='raise')
    return 1.0 - scores.mean()

Error in train_function (#3): The 'eta0' parameter of cross_val_score must be a float in the range [0.0, inf). Got None instead.
Running train_function code:
from sklearn.model_selection import StratifiedKFold, cross_val_score
from sklearn.linear_model import SGDClassifier
from typing import Any
from ConfigSpace import Configuration

def train(cfg: Configuration, seed: int, dataset: Any) -> float:
    X: Any = dataset['X']
    y: Any = dataset['y']
    learning_rate: str = cfg.get('learning_rate')
    alpha: float = cfg.get('alpha')
    max_iter: int = cfg.get('max_iter')
    eta0: float = cfg.get('eta0')

    params: dict = {
        'loss': 'log_loss',
        'penalty': 'l2',
        'learning_rate': learning_rate,
        'alpha': alpha,
        'max_iter': max_iter,
        'random_state': seed,
    }

    if learning_rate in ['constant', 'invscaling', 'adaptive']:
        params['eta0'] = eta0

    model: SGDClassifier = SGDClassifier(**params)
    cv: StratifiedKFold = StratifiedKFold(n_splits=5, shuffle=True, random_state=seed)
    scores: Any = cross_val_score(model, X, y, cv=cv, scoring='accuracy', error_score='raise')
    return 1.0 - scores.mean()

Error in train_function (#4): The 'eta0' parameter of cross_val_score must be a float in the range [0.0, inf). Got None instead.
Running train_function code:
from sklearn.model_selection import StratifiedKFold, cross_val_score
from sklearn.linear_model import SGDClassifier
from typing import Any
from ConfigSpace import Configuration

def train(cfg: Configuration, seed: int, dataset: Any) -> float:
    X: Any = dataset['X']
    y: Any = dataset['y']
    learning_rate: str = cfg.get('learning_rate')
    alpha: float = cfg.get('alpha')
    max_iter: int = cfg.get('max_iter')
    eta0: float = cfg.get('eta0')

    params: dict = {
        'loss': 'log_loss',
        'penalty': 'l2',
        'learning_rate': learning_rate,
        'alpha': alpha,
        'max_iter': max_iter,
        'random_state': seed,
        'eta0': eta0 if learning_rate in ['constant', 'invscaling', 'adaptive'] else 0.1
    }

    model: SGDClassifier = SGDClassifier(**params)
    cv: StratifiedKFold = StratifiedKFold(n_splits=5, shuffle=True, random_state=seed)
    scores: Any = cross_val_score(model, X, y, cv=cv, scoring='accuracy', error_score='raise')
    return 1.0 - scores.mean()

Error in train_function (#5): The 'eta0' parameter of cross_val_score must be a float in the range [0.0, inf). Got None instead.
Retry limit reached for train_function. Fetching fresh code from LLM.
Running train_function code:
from sklearn.model_selection import StratifiedKFold, cross_val_score
from sklearn.linear_model import SGDClassifier
from typing import Any
from ConfigSpace import Configuration

def train(cfg: Configuration, seed: int, dataset: Any) -> float:
    X: Any = dataset['X']
    y: Any = dataset['y']
    learning_rate: str = cfg.get('learning_rate')
    alpha: float = cfg.get('alpha')
    max_iter: int = cfg.get('max_iter')
    eta0: float = cfg.get('eta0')

    C: float = 1.0 / alpha
    params: dict = {
        'loss': 'log_loss',
        'penalty': 'l2',
        'learning_rate': learning_rate,
        'C': C,
        'max_iter': max_iter,
        'warm_start': True,
        'random_state': seed,
    }

    if learning_rate == 'constant':
        params['eta0'] = eta0

    model: SGDClassifier = SGDClassifier(**params)
    cv: StratifiedKFold = StratifiedKFold(n_splits=5, shuffle=True, random_state=seed)
    scores: Any = cross_val_score(model, X, y, cv=cv, scoring='accuracy')
    return 1.0 - scores.mean()

Error in train_function (#1): __init__() got an unexpected keyword argument 'C'
Running train_function code:
from sklearn.model_selection import StratifiedKFold, cross_val_score
from sklearn.linear_model import SGDClassifier
from typing import Any
from ConfigSpace import Configuration

def train(cfg: Configuration, seed: int, dataset: Any) -> float:
    X: Any = dataset['X']
    y: Any = dataset['y']
    learning_rate: str = cfg.get('learning_rate')
    alpha: float = cfg.get('alpha')
    max_iter: int = cfg.get('max_iter')
    eta0: float = cfg.get('eta0')

    params: dict = {
        'loss': 'log_loss',
        'penalty': 'l2',
        'learning_rate': learning_rate,
        'alpha': alpha,
        'max_iter': max_iter,
        'warm_start': True,
        'random_state': seed,
    }

    if learning_rate == 'constant' or learning_rate == 'invscaling' or learning_rate == 'adaptive':
        params['eta0'] = eta0 if eta0 is not None else 0.1

    model: SGDClassifier = SGDClassifier(**params)
    cv: StratifiedKFold = StratifiedKFold(n_splits=5, shuffle=True, random_state=seed)
    scores: Any = cross_val_score(model, X, y, cv=cv, scoring='accuracy', error_score='raise')
    return 1.0 - scores.mean()

Training executed, loss: 0.040000000000000036
Running config code:
from ConfigSpace import ConfigurationSpace, Categorical, Float, Integer, EqualsCondition, ForbiddenEqualsClause, ForbiddenAndConjunction

def get_configspace():
    cs = ConfigurationSpace(seed=1234)
    learning_rate = Categorical("learning_rate", ["adaptive", "constant"])
    alpha = Float("alpha", bounds=(1e-6, 1e-1), log=True)
    max_iter = Integer("max_iter", bounds=(100, 1000))
    eta0 = Float("eta0", bounds=(1e-4, 1.0), log=True)
    early_stopping = Categorical("early_stopping", [True, False], default=True)

    cs.add([learning_rate, alpha, max_iter, eta0, early_stopping])

    cond = EqualsCondition(eta0, learning_rate, "constant")
    cs.add_condition(cond)

    forbidden_clause = ForbiddenAndConjunction(
        ForbiddenEqualsClause(learning_rate, "adaptive"),
        ForbiddenEqualsClause(eta0, eta0.default_value)
    )
    cs.add_forbidden_clause(forbidden_clause)

    return cs

Configuration space generated: Configuration space object:
  Hyperparameters:
    alpha, Type: UniformFloat, Range: [1e-06, 0.1], Default: 0.000316227766, on log-scale
    early_stopping, Type: Categorical, Choices: {True, False}, Default: True
    eta0, Type: UniformFloat, Range: [0.0001, 1.0], Default: 0.01, on log-scale
    learning_rate, Type: Categorical, Choices: {adaptive, constant}, Default: adaptive
    max_iter, Type: UniformInteger, Range: [100, 1000], Default: 550
  Conditions:
    eta0 | learning_rate == 'constant'
  Forbidden Clauses:
    (Forbidden: learning_rate == 'adaptive' && Forbidden: eta0 == 0.01)

Running scenario code:
from smac import Scenario

def generate_scenario(cs):
    scenario = Scenario({
        "run_obj": "quality",
        "output_dir": "./automl_results",
        "shared_model": False,
        "deterministic": False,
        "limit_resources": True,
        "cs": cs
    })
    return scenario

Scenario generated: Scenario(configspace={'run_obj': 'quality', 'output_dir': './automl_results', 'shared_model': False, 'deterministic': False, 'limit_resources': True, 'cs': Configuration space object:
  Hyperparameters:
    alpha, Type: UniformFloat, Range: [1e-06, 0.1], Default: 0.000316227766, on log-scale
    early_stopping, Type: Categorical, Choices: {True, False}, Default: True
    eta0, Type: UniformFloat, Range: [0.0001, 1.0], Default: 0.01, on log-scale
    learning_rate, Type: Categorical, Choices: {adaptive, constant}, Default: adaptive
    max_iter, Type: UniformInteger, Range: [100, 1000], Default: 550
  Conditions:
    eta0 | learning_rate == 'constant'
  Forbidden Clauses:
    (Forbidden: learning_rate == 'adaptive' && Forbidden: eta0 == 0.01)
}, name=None, output_directory=PosixPath('smac3_output'), deterministic=False, objectives='cost', crash_cost=inf, termination_cost_threshold=inf, walltime_limit=inf, cputime_limit=inf, trial_walltime_limit=None, trial_memory_limit=None, n_trials=100, use_default_config=False, instances=None, instance_features=None, min_budget=None, max_budget=None, seed=0, n_workers=1)
Generated training function code:
```python
from sklearn.model_selection import StratifiedKFold, cross_val_score
from sklearn.linear_model import SGDClassifier
from typing import Any
from ConfigSpace import Configuration

def train(cfg: Configuration, seed: int, dataset: Any) -> float:
    X: Any = dataset['X']
    y: Any = dataset['y']
    learning_rate: str = cfg.get('learning_rate')
    alpha: float = cfg.get('alpha')
    max_iter: int = cfg.get('max_iter')
    eta0: float = cfg.get('eta0')

    C: float = 1.0 / alpha
    params: dict = {
        'loss': 'log_loss',
        'penalty': 'l2',
        'learning_rate': learning_rate,
        'alpha': alpha,
        'max_iter': max_iter,
        'warm_start': True,
        'random_state': seed,
        'eta0': eta0 if learning_rate == 'constant' else 0.0
    }

    model: SGDClassifier = SGDClassifier(**params)
    cv: StratifiedKFold = StratifiedKFold(n_splits=5, shuffle=True, random_state=seed)
    scores: Any = cross_val_score(model, X, y, cv=cv, scoring='accuracy')
    return 1.0 - scores.mean()
```
Running train_function code:
from sklearn.model_selection import StratifiedKFold, cross_val_score
from sklearn.linear_model import SGDClassifier
from typing import Any
from ConfigSpace import Configuration

def train(cfg: Configuration, seed: int, dataset: Any) -> float:
    X: Any = dataset['X']
    y: Any = dataset['y']
    learning_rate: str = cfg.get('learning_rate')
    alpha: float = cfg.get('alpha')
    max_iter: int = cfg.get('max_iter')
    eta0: float = cfg.get('eta0')

    C: float = 1.0 / alpha
    params: dict = {
        'loss': 'log_loss',
        'penalty': 'l2',
        'learning_rate': learning_rate,
        'alpha': alpha,
        'max_iter': max_iter,
        'warm_start': True,
        'random_state': seed,
        'eta0': eta0 if learning_rate == 'constant' else 0.0
    }

    model: SGDClassifier = SGDClassifier(**params)
    cv: StratifiedKFold = StratifiedKFold(n_splits=5, shuffle=True, random_state=seed)
    scores: Any = cross_val_score(model, X, y, cv=cv, scoring='accuracy')
    return 1.0 - scores.mean()

Error in train_function (#1): 
All the 5 fits failed.
It is very likely that your model is misconfigured.
You can try to debug the error by setting error_score='raise'.

Below are more details about the failures:
--------------------------------------------------------------------------------
5 fits failed with the following error:
Traceback (most recent call last):
  File "/Users/amirrezaalasti/.pyenv/versions/3.9.13/lib/python3.9/site-packages/sklearn/model_selection/_validation.py", line 888, in _fit_and_score
    estimator.fit(X_train, y_train, **fit_params)
  File "/Users/amirrezaalasti/.pyenv/versions/3.9.13/lib/python3.9/site-packages/sklearn/base.py", line 1473, in wrapper
    return fit_method(estimator, *args, **kwargs)
  File "/Users/amirrezaalasti/.pyenv/versions/3.9.13/lib/python3.9/site-packages/sklearn/linear_model/_stochastic_gradient.py", line 936, in fit
    self._more_validate_params()
  File "/Users/amirrezaalasti/.pyenv/versions/3.9.13/lib/python3.9/site-packages/sklearn/linear_model/_stochastic_gradient.py", line 153, in _more_validate_params
    raise ValueError("eta0 must be > 0")
ValueError: eta0 must be > 0

Running train_function code:
from sklearn.model_selection import StratifiedKFold, cross_val_score
from sklearn.linear_model import SGDClassifier
from typing import Any
from ConfigSpace import Configuration

def train(cfg: Configuration, seed: int, dataset: Any) -> float:
    X: Any = dataset['X']
    y: Any = dataset['y']
    learning_rate: str = cfg.get('learning_rate')
    alpha: float = cfg.get('alpha')
    max_iter: int = cfg.get('max_iter')
    eta0: float = cfg.get('eta0')

    C: float = 1.0 / alpha
    params: dict = {
        'loss': 'log_loss',
        'penalty': 'l2',
        'learning_rate': learning_rate,
        'alpha': alpha,
        'max_iter': max_iter,
        'warm_start': True,
        'random_state': seed,
        'eta0': eta0 if learning_rate in ['constant', 'invscaling', 'adaptive'] else 0.1
    }

    model: SGDClassifier = SGDClassifier(**params)
    cv: StratifiedKFold = StratifiedKFold(n_splits=5, shuffle=True, random_state=seed)
    scores: Any = cross_val_score(model, X, y, cv=cv, scoring='accuracy')
    return 1.0 - scores.mean()

Error in train_function (#2): 
All the 5 fits failed.
It is very likely that your model is misconfigured.
You can try to debug the error by setting error_score='raise'.

Below are more details about the failures:
--------------------------------------------------------------------------------
5 fits failed with the following error:
Traceback (most recent call last):
  File "/Users/amirrezaalasti/.pyenv/versions/3.9.13/lib/python3.9/site-packages/sklearn/model_selection/_validation.py", line 888, in _fit_and_score
    estimator.fit(X_train, y_train, **fit_params)
  File "/Users/amirrezaalasti/.pyenv/versions/3.9.13/lib/python3.9/site-packages/sklearn/base.py", line 1466, in wrapper
    estimator._validate_params()
  File "/Users/amirrezaalasti/.pyenv/versions/3.9.13/lib/python3.9/site-packages/sklearn/base.py", line 666, in _validate_params
    validate_parameter_constraints(
  File "/Users/amirrezaalasti/.pyenv/versions/3.9.13/lib/python3.9/site-packages/sklearn/utils/_param_validation.py", line 95, in validate_parameter_constraints
    raise InvalidParameterError(
sklearn.utils._param_validation.InvalidParameterError: The 'eta0' parameter of SGDClassifier must be a float in the range [0.0, inf). Got None instead.

Running train_function code:
from sklearn.model_selection import StratifiedKFold, cross_val_score
from sklearn.linear_model import SGDClassifier
from typing import Any
from ConfigSpace import Configuration

def train(cfg: Configuration, seed: int, dataset: Any) -> float:
    X: Any = dataset['X']
    y: Any = dataset['y']
    learning_rate: str = cfg.get('learning_rate')
    alpha: float = cfg.get('alpha')
    max_iter: int = cfg.get('max_iter')
    eta0: float = cfg.get('eta0')

    C: float = 1.0 / alpha
    params: dict = {
        'loss': 'log_loss',
        'penalty': 'l2',
        'learning_rate': learning_rate,
        'alpha': alpha,
        'max_iter': max_iter,
        'warm_start': True,
        'random_state': seed,
    }

    if learning_rate in ['constant', 'invscaling', 'adaptive']:
        params['eta0'] = eta0 if eta0 is not None and eta0 > 0 else 0.1
    else:
        params['eta0'] = 0.1

    model: SGDClassifier = SGDClassifier(**params)
    cv: StratifiedKFold = StratifiedKFold(n_splits=5, shuffle=True, random_state=seed)
    scores: Any = cross_val_score(model, X, y, cv=cv, scoring='accuracy', error_score='raise')
    return 1.0 - scores.mean()

Training executed, loss: 0.040000000000000036
